Workbook
Name Asset_Name: Business_Assets!$B$2:$B$11
Name Business_Asset_Name: Business_Assets!$B$2:$B$14
Name Risk_ID: Risk_Scenarios!#REF!
Name Risk_ID_: Risk_Scenarios!$I$2:$I$31
Name Theat_event: Risk_Scenarios!$B$2
Name Threat_Event: Risk_Scenarios!$B$2

Sheet Project_Context
A3: Risk Assessment Spreadsheet
A4: Use to Identify, Assess and Take Action to Treat Risks
A5: Department/Unit Name: | F5: Developed by:Selman Suliman
A6: Project Name: | F6: sulimanselman31@gmail.com
A7: Completed By:
A8: Date Completed:
A9: Date of Next Risk Assessment:
A12: Assessment Objective
A16: In-Scope
A20: Out-of-Scope
A24: Assumptions
A27: Trust Boundaries
A32: Risk Criteria | B32: Purpose This document formally describes The Risk assessment Criteria used within the risk assessment tool to identify, structure, analyze, and quantify information security risks. The intent is to codify the methodologies already embedded in the tool’s structure, worksheets, and calculations, so the assessment process becomes auditable, explainable, and internally consistent.
B37: Methodological Scope The tool implements a qualitative–semi quantitative risk assessment approach aligned conceptually with ISO/IEC 27005 and NIST SP 800 30, using structured decomposition and scoring techniques. The methodologies applied are: 1. Asset based risk assessment 2. Scenario based risk identification 3. Threat–vulnerability coupling 4. Semi-quantitative likelihood estimation 5. Semi-quantitative impact estimation 6. Risk scoring via ordinal multiplication 7. Relative risk ranking and prioritization Each methodology is detailed below exactly as used by the tool.
B52: 1. Asset Based Assessment Approach Method Used Asset Based Risk Assessment How It Is Implemented The tool distinguishes between: • Business Assets (what has value to the organization) • Supporting Assets (what enables or supports business assets) Risk is assessed only in relation to business assets, while supporting assets are used to: • Explain exposure paths • Ground scenarios in technical reality Methodological Rationale This reflects the ISO 27005 principle that: risk exists only where business value exists The tool therefore avoids treating infrastructure components as risk subjects by themselves.
B67: 2. Scenario Based Risk Identification Method Used Risk Scenario Decomposition How It Is Implemented Each risk is expressed as a scenario, implicitly following the structure: A threat exploits a vulnerability affecting a supporting asset, resulting in impact on a business asset. Scenarios are uniquely identified and assessed individually. Methodological Rationale Scenario based assessment: • Prevents abstract or generic risks • Forces traceability from cause to consequence • Enables differentiated likelihood and impact scoring This aligns with ISO 27005 and NIST SP 800 30 scenario modeling practices.
B82: 3. Threat–Vulnerability Coupling Method Used Conditional Risk Existence Model How It Is Implemented The tool assumes that: • Threats are contextual drivers • Vulnerabilities are enabling conditions • Risk materializes only when both are present within a scenario Threats and vulnerabilities are maintained as structured inputs and referenced by scenarios Methodological Rationale This avoids: • Treating vulnerabilities as risks • Treating threats as risks Instead, risk is evaluated at the intersection, which is consistent with ISO 27005 risk formulation
B98: 4. Likelihood Estimation Criteria Method Used semi- quantitative Ordinal Likelihood Scoring How It Is Implemented Likelihood is estimated per scenario using an ordinal scale (e.g., Low → High), internally represented numerically for calculation purposes. The likelihood score implicitly reflects: • Threat presence • Exposure of the supporting asset • Ease of exploitation Likelihood Score= Vulnerability × Threat Considering applied controls effect on vulnerability exploitation by the threat.
B110: 5. Impact Assessment Criteria Method Used: Multi-Dimensional Semi-Quantitative Impact Assessment How It Is Implemented? Impact is assessed across multiple dimensions, including Confidentiality, Integrity, Availability, Financial, Legal, and Operational impacts. For each scenario, the worst credible impact on the associated business asset is evaluated (considering the existing controls), and the results are aggregated into a single composite impact score for comparison and prioritization, the higher dimention score will be chosen (what we fear the most).
B117: 6. Risk Scoring Methodology Method Used Ordinal Risk Matrix Calculation 5*5 How It Is Implemented Risk level is calculated as: Risk Score = Likelihood × Impact Both inputs are ordinal values mapped to numeric ranges solely for ranking purposes as the following:
B126: Risk Level | C126: Score 5*5 | D126: Color | E126: Risk Appetite | F126: These values and estimations may be adjusted in accordance with the organization’s established Risk Criteria
B127: Critical | C127: 16-25 | D127: Red | E127: Not Acceptable
B128: High | C128: 11-15 | D128: Orange
B129: Medium | C129: 6-10 | D129: Yellow | E129: Tolerable with Monitoring
B130: Low | C130: 1-5 | D130: Green | E130: Acceptable
B131: Note You can edit this tool to suite your Risk Criteria as Assessment Standards and Methodology. This tool comes with R-01 Risk assessment process as an example to clarify how to use the tool. The locked cells are always an output for the input cells, so don't mess with.

Sheet Business_Assets
A1: Business Asset ID | B1: Asset Name | C1: Description | D1: Asset Value
A2: A-01 | B2: ERP System | D2: medium
A3: A-02 | B3: Payment System | D3: high

Sheet Supporting_Assets
A1: Supporting Asset ID | B1: Asset Name | C1: Type | D1: Linked Business Asset | E1: Owner

Sheet Vulnerabilities
A1: Vulnerability ID | B1: Vulnerability | C1: Supporting Asset | D1: CVSS Score (0-10) | E1: Exploitability index | F1: Preventive Controls (only) | G1: Control Adequacy | H1: Control Adequacy score | I1: Residual Vulnerability Score | J1: CVSS severity levels are used as the primary indicator of vulnerability exploitability in accordance with FIRST CVSS specifications. | M1: Control Adequacy Scale
A2: Vul-1 | B2: Weak Password Policy | C2: Citizen DB | D2: 9.5 | E2: =IF(D2="","", IF(D2<4,1, IF(D2<6,2, IF(D2<7,3, IF(D2<9,4, IF(D2<=10,5) ))))) -> 5 | F2: Password Policy | G2: Controls exist but inadequate | H2: =IF(G2="No relevant controls",0, IF(G2="Controls exist but inadequate",1, IF(G2="Partially adequate",2, IF(G2="Adequate and effective",3, IF(G2="Fully adequate and resilient",4,""))))) -> 1 | I2: =IF(OR(E2="", H2=""), "", MAX(1, E2 -H2)) -> 4 | M2: No relevant controls | N2: 0
E3: =IF(D3="","", IF(D3<4,1, IF(D3<6,2, IF(D3<7,3, IF(D3<9,4, IF(D3<=10,5) ))))) | H3: =IF(G3="No relevant controls",0, IF(G3="Controls exist but inadequate",1, IF(G3="Partially adequate",2, IF(G3="Adequate and effective",3, IF(G3="Fully adequate and resilient",4,""))))) | I3: =IF(OR(E3="", H3=""), "", MAX(1, E3 -H3)) | M3: Controls exist but inadequate | N3: 1
E4: =IF(D4="","", IF(D4<4,1, IF(D4<6,2, IF(D4<7,3, IF(D4<9,4, IF(D4<=10,5) ))))) | H4: =IF(G4="No relevant controls",0, IF(G4="Controls exist but inadequate",1, IF(G4="Partially adequate",2, IF(G4="Adequate and effective",3, IF(G4="Fully adequate and resilient",4,""))))) | I4: =IF(OR(E4="", H4=""), "", MAX(1, E4 -H4)) | M4: Partially adequate | N4: 2
E5: =IF(D5="","", IF(D5<4,1, IF(D5<6,2, IF(D5<7,3, IF(D5<9,4, IF(D5<=10,5) ))))) | H5: =IF(G5="No relevant controls",0, IF(G5="Controls exist but inadequate",1, IF(G5="Partially adequate",2, IF(G5="Adequate and effective",3, IF(G5="Fully adequate and resilient",4,""))))) | I5: =IF(OR(E5="", H5=""), "", MAX(1, E5 -H5)) | M5: Adequate and effective | N5: 3
E6: =IF(D6="","", IF(D6<4,1, IF(D6<6,2, IF(D6<7,3, IF(D6<9,4, IF(D6<=10,5) ))))) | H6: =IF(G6="No relevant controls",0, IF(G6="Controls exist but inadequate",1, IF(G6="Partially adequate",2, IF(G6="Adequate and effective",3, IF(G6="Fully adequate and resilient",4,""))))) | I6: =IF(OR(E6="", H6=""), "", MAX(1, E6 -H6)) | J6: cvss range | K6: Exploitability Index | L6: explanation | M6: Fully adequate and resilient | N6: 4
E7: =IF(D7="","", IF(D7<4,1, IF(D7<6,2, IF(D7<7,3, IF(D7<9,4, IF(D7<=10,5) ))))) | H7: =IF(G7="No relevant controls",0, IF(G7="Controls exist but inadequate",1, IF(G7="Partially adequate",2, IF(G7="Adequate and effective",3, IF(G7="Fully adequate and resilient",4,""))))) | I7: =IF(OR(E7="", H7=""), "", MAX(1, E7 -H7)) | J7: 0.1-3.9 | K7: 1 | L7: low
E8: =IF(D8="","", IF(D8<4,1, IF(D8<6,2, IF(D8<7,3, IF(D8<9,4, IF(D8<=10,5) ))))) | H8: =IF(G8="No relevant controls",0, IF(G8="Controls exist but inadequate",1, IF(G8="Partially adequate",2, IF(G8="Adequate and effective",3, IF(G8="Fully adequate and resilient",4,""))))) | I8: =IF(OR(E8="", H8=""), "", MAX(1, E8 -H8)) | J8: 4-5.9 | K8: 2 | L8: medium-low
E9: =IF(D9="","", IF(D9<4,1, IF(D9<6,2, IF(D9<7,3, IF(D9<9,4, IF(D9<=10,5) ))))) | H9: =IF(G9="No relevant controls",0, IF(G9="Controls exist but inadequate",1, IF(G9="Partially adequate",2, IF(G9="Adequate and effective",3, IF(G9="Fully adequate and resilient",4,""))))) | I9: =IF(OR(E9="", H9=""), "", MAX(1, E9 -H9)) | J9: 6-6.9 | K9: 3 | L9: high-medium
E10: =IF(D10="","", IF(D10<4,1, IF(D10<6,2, IF(D10<7,3, IF(D10<9,4, IF(D10<=10,5) ))))) | H10: =IF(G10="No relevant controls",0, IF(G10="Controls exist but inadequate",1, IF(G10="Partially adequate",2, IF(G10="Adequate and effective",3, IF(G10="Fully adequate and resilient",4,""))))) | I10: =IF(OR(E10="", H10=""), "", MAX(1, E10 -H10)) | J10: 7-8.9 | K10: 4 | L10: high
E11: =IF(D11="","", IF(D11<4,1, IF(D11<6,2, IF(D11<7,3, IF(D11<9,4, IF(D11<=10,5) ))))) | H11: =IF(G11="No relevant controls",0, IF(G11="Controls exist but inadequate",1, IF(G11="Partially adequate",2, IF(G11="Adequate and effective",3, IF(G11="Fully adequate and resilient",4,""))))) | I11: =IF(OR(E11="", H11=""), "", MAX(1, E11 -H11)) | J11: 9.0-10 | K11: 5 | L11: critical
E12: =IF(D12="","", IF(D12<4,1, IF(D12<6,2, IF(D12<7,3, IF(D12<9,4, IF(D12<=10,5) ))))) | H12: =IF(G12="No relevant controls",0, IF(G12="Controls exist but inadequate",1, IF(G12="Partially adequate",2, IF(G12="Adequate and effective",3, IF(G12="Fully adequate and resilient",4,""))))) | I12: =IF(OR(E12="", H12=""), "", MAX(1, E12 -H12))
E13: =IF(D13="","", IF(D13<4,1, IF(D13<6,2, IF(D13<7,3, IF(D13<9,4, IF(D13<=10,5) ))))) | H13: =IF(G13="No relevant controls",0, IF(G13="Controls exist but inadequate",1, IF(G13="Partially adequate",2, IF(G13="Adequate and effective",3, IF(G13="Fully adequate and resilient",4,""))))) | I13: =IF(OR(E13="", H13=""), "", MAX(1, E13 -H13))
E14: =IF(D14="","", IF(D14<4,1, IF(D14<6,2, IF(D14<7,3, IF(D14<9,4, IF(D14<=10,5) ))))) | H14: =IF(G14="No relevant controls",0, IF(G14="Controls exist but inadequate",1, IF(G14="Partially adequate",2, IF(G14="Adequate and effective",3, IF(G14="Fully adequate and resilient",4,""))))) | I14: =IF(OR(E14="", H14=""), "", MAX(1, E14 -H14))
E15: =IF(D15="","", IF(D15<4,1, IF(D15<6,2, IF(D15<7,3, IF(D15<9,4, IF(D15<=10,5) ))))) | H15: =IF(G15="No relevant controls",0, IF(G15="Controls exist but inadequate",1, IF(G15="Partially adequate",2, IF(G15="Adequate and effective",3, IF(G15="Fully adequate and resilient",4,""))))) | I15: =IF(OR(E15="", H15=""), "", MAX(1, E15 -H15))
E16: =IF(D16="","", IF(D16<4,1, IF(D16<6,2, IF(D16<7,3, IF(D16<9,4, IF(D16<=10,5) ))))) | H16: =IF(G16="No relevant controls",0, IF(G16="Controls exist but inadequate",1, IF(G16="Partially adequate",2, IF(G16="Adequate and effective",3, IF(G16="Fully adequate and resilient",4,""))))) | I16: =IF(OR(E16="", H16=""), "", MAX(1, E16 -H16))
E17: =IF(D17="","", IF(D17<4,1, IF(D17<6,2, IF(D17<7,3, IF(D17<9,4, IF(D17<=10,5) ))))) | H17: =IF(G17="No relevant controls",0, IF(G17="Controls exist but inadequate",1, IF(G17="Partially adequate",2, IF(G17="Adequate and effective",3, IF(G17="Fully adequate and resilient",4,""))))) | I17: =IF(OR(E17="", H17=""), "", MAX(1, E17 -H17))
E18: =IF(D18="","", IF(D18<4,1, IF(D18<6,2, IF(D18<7,3, IF(D18<9,4, IF(D18<=10,5) ))))) | H18: =IF(G18="No relevant controls",0, IF(G18="Controls exist but inadequate",1, IF(G18="Partially adequate",2, IF(G18="Adequate and effective",3, IF(G18="Fully adequate and resilient",4,""))))) | I18: =IF(OR(E18="", H18=""), "", MAX(1, E18 -H18))
E19: =IF(D19="","", IF(D19<4,1, IF(D19<6,2, IF(D19<7,3, IF(D19<9,4, IF(D19<=10,5) ))))) | H19: =IF(G19="No relevant controls",0, IF(G19="Controls exist but inadequate",1, IF(G19="Partially adequate",2, IF(G19="Adequate and effective",3, IF(G19="Fully adequate and resilient",4,""))))) | I19: =IF(OR(E19="", H19=""), "", MAX(1, E19 -H19))
E20: =IF(D20="","", IF(D20<4,1, IF(D20<6,2, IF(D20<7,3, IF(D20<9,4, IF(D20<=10,5) ))))) | H20: =IF(G20="No relevant controls",0, IF(G20="Controls exist but inadequate",1, IF(G20="Partially adequate",2, IF(G20="Adequate and effective",3, IF(G20="Fully adequate and resilient",4,""))))) | I20: =IF(OR(E20="", H20=""), "", MAX(1, E20 -H20))
E21: =IF(D21="","", IF(D21<4,1, IF(D21<6,2, IF(D21<7,3, IF(D21<9,4, IF(D21<=10,5) ))))) | H21: =IF(G21="No relevant controls",0, IF(G21="Controls exist but inadequate",1, IF(G21="Partially adequate",2, IF(G21="Adequate and effective",3, IF(G21="Fully adequate and resilient",4,""))))) | I21: =IF(OR(E21="", H21=""), "", MAX(1, E21 -H21))
E22: =IF(D22="","", IF(D22<4,1, IF(D22<6,2, IF(D22<7,3, IF(D22<9,4, IF(D22<=10,5) ))))) | H22: =IF(G22="No relevant controls",0, IF(G22="Controls exist but inadequate",1, IF(G22="Partially adequate",2, IF(G22="Adequate and effective",3, IF(G22="Fully adequate and resilient",4,""))))) | I22: =IF(OR(E22="", H22=""), "", MAX(1, E22 -H22))
E23: =IF(D23="","", IF(D23<4,1, IF(D23<6,2, IF(D23<7,3, IF(D23<9,4, IF(D23<=10,5) ))))) | H23: =IF(G23="No relevant controls",0, IF(G23="Controls exist but inadequate",1, IF(G23="Partially adequate",2, IF(G23="Adequate and effective",3, IF(G23="Fully adequate and resilient",4,""))))) | I23: =IF(OR(E23="", H23=""), "", MAX(1, E23 -H23))
... E31: =IF(D31="","", IF(D31<4,1, IF(D31<6,2, IF(D31<7,3, IF(D31<9,4, IF(D31<=10,5) ))))) | H31: =IF(G31="No relevant controls",0, IF(G31="Controls exist but inadequate",1, IF(G31="Partially adequate",2, IF(G31="Adequate and effective",3, IF(G31="Fully adequate and resilient",4,""))))) | I31: =IF(OR(E31="", H31=""), "", MAX(1, E31 -H31))
E32: =IF(D32="","", IF(D32<4,1, IF(D32<6,2, IF(D32<7,3, IF(D32<9,4, IF(D32<=10,5) ))))) | H32: =IF(G32="No relevant controls",0, IF(G32="Controls exist but inadequate",1, IF(G32="Partially adequate",2, IF(G32="Adequate and effective",3, IF(G32="Fully adequate and resilient",4,"")))))
E33: =IF(D33="","", IF(D33<4,1, IF(D33<6,2, IF(D33<7,3, IF(D33<9,4, IF(D33<=10,5) )))))
E34: =IF(D34="","", IF(D34<4,1, IF(D34<6,2, IF(D34<7,3, IF(D34<9,4, IF(D34<=10,5) )))))
E35: =IF(D35="","", IF(D35<4,1, IF(D35<6,2, IF(D35<7,3, IF(D35<9,4, IF(D35<10,5) )))))
E36: =IF(D36="","", IF(D36<4,1, IF(D36<6,2, IF(D36<7,3, IF(D36<9,4, IF(D36<10,5) )))))
E37: =IF(D37="","", IF(D37<4,1, IF(D37<6,2, IF(D37<7,3, IF(D37<9,4, IF(D37<10,5) )))))
E38: =IF(D38="","", IF(D38<4,1, IF(D38<6,2, IF(D38<7,3, IF(D38<9,4, IF(D38<10,5) )))))
E39: =IF(D39="","", IF(D39<4,1, IF(D39<6,2, IF(D39<7,3, IF(D39<9,4, IF(D39<10,5) )))))
E40: =IF(D40="","", IF(D40<4,1, IF(D40<6,2, IF(D40<7,3, IF(D40<9,4, IF(D40<10,5) )))))
E41: =IF(D41="","", IF(D41<4,1, IF(D41<6,2, IF(D41<7,3, IF(D41<9,4, IF(D41<10,5) )))))
E42: =IF(D42="","", IF(D42<4,1, IF(D42<6,2, IF(D42<7,3, IF(D42<9,4, IF(D42<10,5) )))))
E43: =IF(D43="","", IF(D43<4,1, IF(D43<6,2, IF(D43<7,3, IF(D43<9,4, IF(D43<10,5) )))))
E44: =IF(D44="","", IF(D44<4,1, IF(D44<6,2, IF(D44<7,3, IF(D44<9,4, IF(D44<10,5) )))))
E45: =IF(D45="","", IF(D45<4,1, IF(D45<6,2, IF(D45<7,3, IF(D45<9,4, IF(D45<10,5) )))))
E46: =IF(D46="","", IF(D46<4,1, IF(D46<6,2, IF(D46<7,3, IF(D46<9,4, IF(D46<10,5) )))))
... E56: =IF(D56="","", IF(D56<4,1, IF(D56<6,2, IF(D56<7,3, IF(D56<9,4, IF(D56<10,5) )))))

Sheet Risk_Scenarios
A1: Threat ID | B1: Threat event | C1: Threat Category | D1: Threat Source | E1: Vulnerability/Weakness | F1: Type of Risk Source | G1: Affected Business Asset | H1: Operational Risk Scenario | I1: Risk ID | J1: Description
A2: Th-01 | B2: Unauthorized access by an attacker | C2: human actions | D2: External | E2: =IF(Vulnerabilities!B2="","",Vulnerabilities!B2) -> Weak Password Policy | F2: D | G2: Payment System | H2: Citizen personal data leaks due to weak authentication controls | I2: R-01
E3: =IF(Vulnerabilities!B3="","",Vulnerabilities!B3) | G3: Payment System
E4: =IF(Vulnerabilities!B4="","",Vulnerabilities!B4)
E5: =IF(Vulnerabilities!B5="","",Vulnerabilities!B5)
E6: =IF(Vulnerabilities!B6="","",Vulnerabilities!B6)
E7: =IF(Vulnerabilities!B7="","",Vulnerabilities!B7)
E8: =IF(Vulnerabilities!B8="","",Vulnerabilities!B8)
E9: =IF(Vulnerabilities!B9="","",Vulnerabilities!B9)
E10: =IF(Vulnerabilities!B10="","",Vulnerabilities!B10)
E11: =IF(Vulnerabilities!B11="","",Vulnerabilities!B11)
E12: =IF(Vulnerabilities!B12="","",Vulnerabilities!B12)
E13: =IF(Vulnerabilities!B13="","",Vulnerabilities!B13)
E14: =IF(Vulnerabilities!B14="","",Vulnerabilities!B14)
E15: =IF(Vulnerabilities!B15="","",Vulnerabilities!B15)
... E32: =IF(Vulnerabilities!B32="","",Vulnerabilities!B32)

Sheet likelihood
A1: Risk ID | B1: Threat Event | C1: =IF(Vulnerabilities!B1="","",Vulnerabilities!B1) -> Vulnerability | D1: Residual Vulnerability score | E1: Threat Activity / Frequency | F1: Likelihood | G1: Threat Activity / Frequency Scale
A2: =IF(Risk_Scenarios!I2="","",Risk_Scenarios!I2) -> R-01 | B2: =IF(Risk_Scenarios!B2="","",Risk_Scenarios!B2) -> Unauthorized access by an attacker | C2: =IF(Vulnerabilities!B2="","",Vulnerabilities!B2) -> Weak Password Policy | D2: =IF(Vulnerabilities!I2="","",Vulnerabilities!I2) -> 4 | E2: 4 | F2: =IFERROR(ROUNDUP((D2*E2)/5,0),"") -> 4 | G2: Score | H2: Term | I2: Frequency
A3: =IF(Risk_Scenarios!I3="","",Risk_Scenarios!I3) | B3: =IF(Risk_Scenarios!B3="","",Risk_Scenarios!B3) | C3: =IF(Vulnerabilities!B3="","",Vulnerabilities!B3) | D3: =IF(Vulnerabilities!I3="","",Vulnerabilities!I3) | F3: =IFERROR(ROUNDUP((D3*E3)/5,0),"") | G3: 1 | H3: Rare | I3: Occurs about once every 5 years
A4: =IF(Risk_Scenarios!I4="","",Risk_Scenarios!I4) | B4: =IF(Risk_Scenarios!B4="","",Risk_Scenarios!B4) | C4: =IF(Vulnerabilities!B4="","",Vulnerabilities!B4) | D4: =IF(Vulnerabilities!I4="","",Vulnerabilities!I4) | F4: =IFERROR(ROUNDUP((D4*E4)/5,0),"") | G4: 2 | H4: Unlikely | I4: Occurs once every 3–5 years
A5: =IF(Risk_Scenarios!I5="","",Risk_Scenarios!I5) | B5: =IF(Risk_Scenarios!B5="","",Risk_Scenarios!B5) | C5: =IF(Vulnerabilities!B5="","",Vulnerabilities!B5) | D5: =IF(Vulnerabilities!I5="","",Vulnerabilities!I5) | F5: =IFERROR(ROUNDUP((D5*E5)/5,0),"") | G5: 3 | H5: Possible | I5: Occurs about once per year
A6: =IF(Risk_Scenarios!I6="","",Risk_Scenarios!I6) | B6: =IF(Risk_Scenarios!B6="","",Risk_Scenarios!B6) | C6: =IF(Vulnerabilities!B6="","",Vulnerabilities!B6) | D6: =IF(Vulnerabilities!I6="","",Vulnerabilities!I6) | F6: =IFERROR(ROUNDUP((D6*E6)/5,0),"") | G6: 4 | H6: Likely | I6: Occurs several times per year
A7: =IF(Risk_Scenarios!I7="","",Risk_Scenarios!I7) | B7: =IF(Risk_Scenarios!B7="","",Risk_Scenarios!B7) | C7: =IF(Vulnerabilities!B7="","",Vulnerabilities!B7) | D7: =IF(Vulnerabilities!I7="","",Vulnerabilities!I7) | F7: =IFERROR(ROUNDUP((D7*E7)/5,0),"") | G7: 5 | H7: Frequent | I7: Occurs several times per month/week/almost daily
A8: =IF(Risk_Scenarios!I8="","",Risk_Scenarios!I8) | B8: =IF(Risk_Scenarios!B8="","",Risk_Scenarios!B8) | C8: =IF(Vulnerabilities!B8="","",Vulnerabilities!B8) | D8: =IF(Vulnerabilities!I8="","",Vulnerabilities!I8) | F8: =IFERROR(ROUNDUP((D8*E8)/5,0),"") | G8: Likelihood Mapping
A9: =IF(Risk_Scenarios!I9="","",Risk_Scenarios!I9) | B9: =IF(Risk_Scenarios!B9="","",Risk_Scenarios!B9) | C9: =IF(Vulnerabilities!B9="","",Vulnerabilities!B9) | D9: =IF(Vulnerabilities!I9="","",Vulnerabilities!I9) | F9: =IFERROR(ROUNDUP((D9*E9)/5,0),"") | G9: 1 | I9: 1-5
A10: =IF(Risk_Scenarios!I10="","",Risk_Scenarios!I10) | B10: =IF(Risk_Scenarios!B10="","",Risk_Scenarios!B10) | C10: =IF(Vulnerabilities!B10="","",Vulnerabilities!B10) | D10: =IF(Vulnerabilities!I10="","",Vulnerabilities!I10) | F10: =IFERROR(ROUNDUP((D10*E10)/5,0),"") | G10: 2 | I10: 6-10
A11: =IF(Risk_Scenarios!I11="","",Risk_Scenarios!I11) | B11: =IF(Risk_Scenarios!B11="","",Risk_Scenarios!B11) | C11: =IF(Vulnerabilities!B11="","",Vulnerabilities!B11) | D11: =IF(Vulnerabilities!I11="","",Vulnerabilities!I11) | F11: =IFERROR(ROUNDUP((D11*E11)/5,0),"") | G11: 3 | I11: 11-15
A12: =IF(Risk_Scenarios!I12="","",Risk_Scenarios!I12) | B12: =IF(Risk_Scenarios!B12="","",Risk_Scenarios!B12) | C12: =IF(Vulnerabilities!B12="","",Vulnerabilities!B12) | D12: =IF(Vulnerabilities!I12="","",Vulnerabilities!I12) | F12: =IFERROR(ROUNDUP((D12*E12)/5,0),"") | G12: 4 | I12: 16-20
A13: =IF(Risk_Scenarios!I13="","",Risk_Scenarios!I13) | B13: =IF(Risk_Scenarios!B13="","",Risk_Scenarios!B13) | C13: =IF(Vulnerabilities!B13="","",Vulnerabilities!B13) | D13: =IF(Vulnerabilities!I13="","",Vulnerabilities!I13) | F13: =IFERROR(ROUNDUP((D13*E13)/5,0),"") | G13: 5 | I13: 21-25
A14: =IF(Risk_Scenarios!I14="","",Risk_Scenarios!I14) | B14: =IF(Risk_Scenarios!B14="","",Risk_Scenarios!B14) | C14: =IF(Vulnerabilities!B14="","",Vulnerabilities!B14) | D14: =IF(Vulnerabilities!I14="","",Vulnerabilities!I14) | F14: =IFERROR(ROUNDUP((D14*E14)/5,0),"")
A15: =IF(Risk_Scenarios!I15="","",Risk_Scenarios!I15) | B15: =IF(Risk_Scenarios!B15="","",Risk_Scenarios!B15) | C15: =IF(Vulnerabilities!B15="","",Vulnerabilities!B15) | D15: =IF(Vulnerabilities!I15="","",Vulnerabilities!I15) | F15: =IFERROR(ROUNDUP((D15*E15)/5,0),"")
A16: =IF(Risk_Scenarios!I16="","",Risk_Scenarios!I16) | B16: =IF(Risk_Scenarios!B16="","",Risk_Scenarios!B16) | C16: =IF(Vulnerabilities!B16="","",Vulnerabilities!B16) | D16: =IF(Vulnerabilities!I16="","",Vulnerabilities!I16) | F16: =IFERROR(ROUNDUP((D16*E16)/5,0),"")
A17: =IF(Risk_Scenarios!I17="","",Risk_Scenarios!I17) | B17: =IF(Risk_Scenarios!B17="","",Risk_Scenarios!B17) | C17: =IF(Vulnerabilities!B17="","",Vulnerabilities!B17) | D17: =IF(Vulnerabilities!I17="","",Vulnerabilities!I17) | F17: =IFERROR(ROUNDUP((D17*E17)/5,0),"")
A18: =IF(Risk_Scenarios!I18="","",Risk_Scenarios!I18) | B18: =IF(Risk_Scenarios!B18="","",Risk_Scenarios!B18) | C18: =IF(Vulnerabilities!B18="","",Vulnerabilities!B18) | D18: =IF(Vulnerabilities!I18="","",Vulnerabilities!I18) | F18: =IFERROR(ROUNDUP((D18*E18)/5,0),"")
A19: =IF(Risk_Scenarios!I19="","",Risk_Scenarios!I19) | B19: =IF(Risk_Scenarios!B19="","",Risk_Scenarios!B19) | C19: =IF(Vulnerabilities!B19="","",Vulnerabilities!B19) | D19: =IF(Vulnerabilities!I19="","",Vulnerabilities!I19) | F19: =IFERROR(ROUNDUP((D19*E19)/5,0),"")
A20: =IF(Risk_Scenarios!I20="","",Risk_Scenarios!I20) | B20: =IF(Risk_Scenarios!B20="","",Risk_Scenarios!B20) | C20: =IF(Vulnerabilities!B20="","",Vulnerabilities!B20) | D20: =IF(Vulnerabilities!I20="","",Vulnerabilities!I20) | F20: =IFERROR(ROUNDUP((D20*E20)/5,0),"")
A21: =IF(Risk_Scenarios!I21="","",Risk_Scenarios!I21) | B21: =IF(Risk_Scenarios!B21="","",Risk_Scenarios!B21) | C21: =IF(Vulnerabilities!B21="","",Vulnerabilities!B21) | D21: =IF(Vulnerabilities!I21="","",Vulnerabilities!I21) | F21: =IFERROR(ROUNDUP((D21*E21)/5,0),"")
A22: =IF(Risk_Scenarios!I22="","",Risk_Scenarios!I22) | B22: =IF(Risk_Scenarios!B22="","",Risk_Scenarios!B22) | C22: =IF(Vulnerabilities!B22="","",Vulnerabilities!B22) | D22: =IF(Vulnerabilities!I22="","",Vulnerabilities!I22) | F22: =IFERROR(ROUNDUP((D22*E22)/5,0),"")
A23: =IF(Risk_Scenarios!I23="","",Risk_Scenarios!I23) | B23: =IF(Risk_Scenarios!B23="","",Risk_Scenarios!B23) | C23: =IF(Vulnerabilities!B23="","",Vulnerabilities!B23) | D23: =IF(Vulnerabilities!I23="","",Vulnerabilities!I23) | F23: =IFERROR(ROUNDUP((D23*E23)/5,0),"")
A24: =IF(Risk_Scenarios!I24="","",Risk_Scenarios!I24) | B24: =IF(Risk_Scenarios!B24="","",Risk_Scenarios!B24) | C24: =IF(Vulnerabilities!B24="","",Vulnerabilities!B24) | D24: =IF(Vulnerabilities!I24="","",Vulnerabilities!I24) | F24: =IFERROR(ROUNDUP((D24*E24)/5,0),"")
A25: =IF(Risk_Scenarios!I25="","",Risk_Scenarios!I25) | B25: =IF(Risk_Scenarios!B25="","",Risk_Scenarios!B25) | C25: =IF(Vulnerabilities!B25="","",Vulnerabilities!B25) | D25: =IF(Vulnerabilities!I25="","",Vulnerabilities!I25) | F25: =IFERROR(ROUNDUP((D25*E25)/5,0),"")
... A31: =IF(Risk_Scenarios!I31="","",Risk_Scenarios!I31) | B31: =IF(Risk_Scenarios!B31="","",Risk_Scenarios!B31) | C31: =IF(Vulnerabilities!B31="","",Vulnerabilities!B31) | D31: =IF(Vulnerabilities!I31="","",Vulnerabilities!I31) | F31: =IFERROR(ROUNDUP((D31*E31)/5,0),"")
F36: =IF(OR(D36="",E36=""), "", D36 * E36)
F37: =IF(OR(D37="",E37=""), "", D37 * E37)
F38: =IF(OR(D38="",E38=""), "", D38 * E38)
F39: =IF(OR(D39="",E39=""), "", D39 * E39)

Sheet Impact_Assessment
A1: Risk ID | B1: Threat Event | C1: Controls(Detective,Corrective) | D1: Control Effectiveness | E1: Confidentiality | F1: Integrity | G1: Availability | H1: Financial (1-5) | I1: Operational (1-5) | J1: Legal (1-5) | K1: Reputational (1-5) | L1: Impact
A2: =IF(Risk_Scenarios!I2="","",Risk_Scenarios!I2) -> R-01 | B2: =IF(Risk_Scenarios!B2="","",Risk_Scenarios!B2) -> Unauthorized access by an attacker | C2: none | D2: 0 | E2: 2 | F2: 2 | G2: 1 | H2: 3 | I2: 3 | J2: 1 | K2: 3 | L2: =IF(OR(E2="",F2="",G2="",H2="",I2="",J2="",K2=""), "",MAX(E2:F2:G2:H2:I2:J2:K2, 0)) -> 3
A3: =IF(Risk_Scenarios!I3="","",Risk_Scenarios!I3) | B3: =IF(Risk_Scenarios!B3="","",Risk_Scenarios!B3) | L3: =IF(OR(E3="",F3="",G3="",H3="",I3="",J3="",K3=""), "",MAX(E3:F3:G3:H3:I3:J3:K3, 0))
A4: =IF(Risk_Scenarios!I4="","",Risk_Scenarios!I4) | B4: =IF(Risk_Scenarios!B4="","",Risk_Scenarios!B4) | L4: =IF(OR(E4="",F4="",G4="",H4="",I4="",J4="",K4=""), "",MAX(E4:F4:G4:H4:I4:J4:K4, 0))
A5: =IF(Risk_Scenarios!I5="","",Risk_Scenarios!I5) | B5: =IF(Risk_Scenarios!B5="","",Risk_Scenarios!B5) | L5: =IF(OR(E5="",F5="",G5="",H5="",I5="",J5="",K5=""), "",MAX(E5:F5:G5:H5:I5:J5:K5, 0))
A6: =IF(Risk_Scenarios!I6="","",Risk_Scenarios!I6) | B6: =IF(Risk_Scenarios!B6="","",Risk_Scenarios!B6) | L6: =IF(OR(E6="",F6="",G6="",H6="",I6="",J6="",K6=""), "",MAX(E6:F6:G6:H6:I6:J6:K6, 0))
A7: =IF(Risk_Scenarios!I7="","",Risk_Scenarios!I7) | B7: =IF(Risk_Scenarios!B7="","",Risk_Scenarios!B7) | L7: =IF(OR(E7="",F7="",G7="",H7="",I7="",J7="",K7=""), "",MAX(E7:F7:G7:H7:I7:J7:K7, 0))
A8: =IF(Risk_Scenarios!I8="","",Risk_Scenarios!I8) | B8: =IF(Risk_Scenarios!B8="","",Risk_Scenarios!B8) | L8: =IF(OR(E8="",F8="",G8="",H8="",I8="",J8="",K8=""), "",MAX(E8:F8:G8:H8:I8:J8:K8, 0))
A9: =IF(Risk_Scenarios!I9="","",Risk_Scenarios!I9) | B9: =IF(Risk_Scenarios!B9="","",Risk_Scenarios!B9) | L9: =IF(OR(E9="",F9="",G9="",H9="",I9="",J9="",K9=""), "",MAX(E9:F9:G9:H9:I9:J9:K9, 0))
A10: =IF(Risk_Scenarios!I10="","",Risk_Scenarios!I10) | B10: =IF(Risk_Scenarios!B10="","",Risk_Scenarios!B10) | L10: =IF(OR(E10="",F10="",G10="",H10="",I10="",J10="",K10=""), "",MAX(E10:F10:G10:H10:I10:J10:K10, 0))
A11: =IF(Risk_Scenarios!I11="","",Risk_Scenarios!I11) | B11: =IF(Risk_Scenarios!B11="","",Risk_Scenarios!B11) | L11: =IF(OR(E11="",F11="",G11="",H11="",I11="",J11="",K11=""), "",MAX(E11:F11:G11:H11:I11:J11:K11, 0))
A12: =IF(Risk_Scenarios!I12="","",Risk_Scenarios!I12) | B12: =IF(Risk_Scenarios!B12="","",Risk_Scenarios!B12) | L12: =IF(OR(E12="",F12="",G12="",H12="",I12="",J12="",K12=""), "",MAX(E12:F12:G12:H12:I12:J12:K12, 0))
A13: =IF(Risk_Scenarios!I13="","",Risk_Scenarios!I13) | B13: =IF(Risk_Scenarios!B13="","",Risk_Scenarios!B13) | L13: =IF(OR(E13="",F13="",G13="",H13="",I13="",J13="",K13=""), "",MAX(E13:F13:G13:H13:I13:J13:K13, 0))
A14: =IF(Risk_Scenarios!I14="","",Risk_Scenarios!I14) | B14: =IF(Risk_Scenarios!B14="","",Risk_Scenarios!B14) | L14: =IF(OR(E14="",F14="",G14="",H14="",I14="",J14="",K14=""), "",MAX(E14:F14:G14:H14:I14:J14:K14, 0))
... A31: =IF(Risk_Scenarios!I31="","",Risk_Scenarios!I31) | B31: =IF(Risk_Scenarios!B31="","",Risk_Scenarios!B31) | L31: =IF(OR(E31="",F31="",G31="",H31="",I31="",J31="",K31=""), "",MAX(E31:F31:G31:H31:I31:J31:K31, 0))
L32: =IF(OR(E32="",F32="",G32="",H32="",I32="",J32="",K32=""), "",MAX(E32:F32:G32:H32:I32:J32:K32, 0))
L33: =IF(OR(E33="",F33="",G33="",H33="",I33="",J33="",K33=""), "",MAX(E33:F33:G33:H33:I33:J33:K33, 0))
L34: =IF(OR(E34="",F34="",G34="",H34="",I34="",J34="",K34=""), "",MAX(E34:F34:G34:H34:I34:J34:K34, 0))
L35: =IF(OR(E35="",F35="",G35="",H35="",I35="",J35="",K35=""), "",MAX(E35:F35:G35:H35:I35:J35:K35, 0))
L36: =IF(OR(E36="",F36="",G36="",H36="",I36="",J36="",K36=""), "",MAX(E36:F36:G36:H36:I36:J36:K36, 0))
L37: =IF(OR(E37="",F37="",G37="",H37="",I37="",J37="",K37=""), "",MAX(E37:F37:G37:H37:I37:J37:K37, 0))
L38: =IF(OR(E38="",F38="",G38="",H38="",I38="",J38="",K38=""), "",MAX(E38:F38:G38:H38:I38:J38:K38, 0))
L39: =IF(OR(E39="",F39="",G39="",H39="",I39="",J39="",K39=""), "",MAX(E39:F39:G39:H39:I39:J39:K39, 0))
L40: =IF(OR(E40="",F40="",G40="",H40="",I40="",J40="",K40=""), "",MAX(E40:F40:G40:H40:I40:J40:K40, 0))
L41: =IF(OR(E41="",F41="",G41="",H41="",I41="",J41="",K41=""), "",MAX(E41:F41:G41:H41:I41:J41:K41, 0))
L42: =IF(OR(E42="",F42="",G42="",H42="",I42="",J42="",K42=""), "",MAX(E42:F42:G42:H42:I42:J42:K42, 0))
L43: =IF(OR(E43="",F43="",G43="",H43="",I43="",J43="",K43=""), "",MAX(E43:F43:G43:H43:I43:J43:K43, 0))
L44: =IF(OR(E44="",F44="",G44="",H44="",I44="",J44="",K44=""), "",MAX(E44:F44:G44:H44:I44:J44:K44, 0))
L45: =IF(OR(E45="",F45="",G48="",H45="",I45="",J45="",K45=""), "",MAX(E45:F45:G45:H45:I45:J45:K45, 0))
L46: =IF(OR(E46="",F46="",G49="",H46="",I46="",J46="",K46=""), "",MAX(E46:F46:G46:H46:I46:J46:K46, 0))
L47: =IF(OR(E47="",F47="",G50="",H47="",I47="",J47="",K47=""), "",MAX(E47:F47:G47:H47:I47:J47:K47, 0))
L48: =IF(OR(E48="",F48="",G51="",H48="",I48="",J48="",K48=""), "",MAX(E48:F48:G48:H48:I48:J48:K48, 0))
L49: =IF(OR(E49="",F49="",G52="",H49="",I49="",J49="",K49=""), "",MAX(E49:F49:G49:H49:I49:J49:K49, 0))
L50: =IF(OR(E50="",F50="",G53="",H50="",I50="",J50="",K50=""), "",MAX(E50:F50:G50:H50:I50:J50:K50, 0))
L51: =IF(OR(E51="",F51="",G54="",H51="",I51="",J51="",K51=""), "",MAX(E51:F51:G51:H51:I51:J51:K51, 0))
L52: =IF(OR(E52="",F52="",G55="",H52="",I52="",J52="",K52=""), "",MAX(E52:F52:G52:H52:I52:J52:K52, 0))
L53: =IF(OR(E53="",F53="",G56="",H53="",I53="",J53="",K53=""), "",MAX(E53:F53:G53:H53:I53:J53:K53, 0))
L54: =IF(OR(E54="",F54="",G57="",H54="",I54="",J54="",K54=""), "",MAX(E54:F54:G54:H54:I54:J54:K54, 0))
L55: =IF(OR(E55="",F55="",G58="",H55="",I55="",J55="",K55=""), "",MAX(E55:F55:G55:H55:I55:J55:K55, 0))
L56: =IF(OR(E56="",F56="",G59="",H56="",I56="",J56="",K56=""), "",MAX(E56:F56:G56:H56:I56:J56:K56, 0))
...

Sheet Inherent_Risk_Scores
A1: Risk Scenario | B1: Risk ID | C1: Likelihood | D1: Impact | E1: Risk Score (Inherent) | F1: Risk Level | G1: Risk Owner | H1: Risk Decision | I1: Risk Treatment | J1: Risk Appetite
A2: =IF(Risk_Scenarios!H2="","",Risk_Scenarios!H2) -> Citizen personal data leaks due to weak authentication controls | B2: =IF(Risk_Scenarios!I2="","",Risk_Scenarios!I2) -> R-01 | C2: =IF(likelihood!F2="","",likelihood!F2) -> 4 | D2: =IF(Impact_Assessment!L2="","",Impact_Assessment!L2) -> 3 | E2: =IF(C2<>"",C2*D2,"") -> 12 | F2: =IF(E2="","", IF(E2<=5,"Low",IF(E2<=10,"Medium", IF(E2<=15,"High","Critical")))) -> High | G2: IT Manager | H2: =IF(E2="","",IF(E2<=$K$4,"Accept","Treat")) -> Treat | I2: Mitigate
A3: =IF(Risk_Scenarios!H3="","",Risk_Scenarios!H3) | B3: =IF(Risk_Scenarios!I3="","",Risk_Scenarios!I3) | C3: =IF(likelihood!F3="","",likelihood!F3) | D3: =IF(Impact_Assessment!L3="","",Impact_Assessment!L3) | E3: =IF(C3<>"",C3*D3,"") | F3: =IF(E3="","", IF(E3<=5,"Low",IF(E3<=10,"Medium", IF(E3<=15,"High","Critical")))) | H3: =IF(E3="","",IF(E3<=$K$4,"Accept","Treat"))
A4: =IF(Risk_Scenarios!H4="","",Risk_Scenarios!H4) | B4: =IF(Risk_Scenarios!I4="","",Risk_Scenarios!I4) | C4: =IF(likelihood!F4="","",likelihood!F4) | D4: =IF(Impact_Assessment!L4="","",Impact_Assessment!L4) | E4: =IF(C4<>"",C4*D4,"") | F4: =IF(E4="","", IF(E4<=5,"Low",IF(E4<=10,"Medium", IF(E4<=15,"High","Critical")))) | H4: =IF(E4="","",IF(E4<=$K$4,"Accept","Treat")) | J4: Max Level | K4: 10
A5: =IF(Risk_Scenarios!H5="","",Risk_Scenarios!H5) | B5: =IF(Risk_Scenarios!I5="","",Risk_Scenarios!I5) | C5: =IF(likelihood!F5="","",likelihood!F5) | D5: =IF(Impact_Assessment!L5="","",Impact_Assessment!L5) | E5: =IF(C5<>"",C5*D5,"") | F5: =IF(E5="","", IF(E5<=5,"Low",IF(E5<=10,"Medium", IF(E5<=15,"High","Critical")))) | H5: =IF(E5="","",IF(E5<=$K$4,"Accept","Treat"))
A6: =IF(Risk_Scenarios!H6="","",Risk_Scenarios!H6) | B6: =IF(Risk_Scenarios!I6="","",Risk_Scenarios!I6) | C6: =IF(likelihood!F6="","",likelihood!F6) | D6: =IF(Impact_Assessment!L6="","",Impact_Assessment!L6) | E6: =IF(C6<>"",C6*D6,"") | F6: =IF(E6="","", IF(E6<=5,"Low",IF(E6<=10,"Medium", IF(E6<=15,"High","Critical")))) | H6: =IF(E6="","",IF(E6<=$K$4,"Accept","Treat"))
A7: =IF(Risk_Scenarios!H7="","",Risk_Scenarios!H7) | B7: =IF(Risk_Scenarios!I7="","",Risk_Scenarios!I7) | C7: =IF(likelihood!F7="","",likelihood!F7) | D7: =IF(Impact_Assessment!L7="","",Impact_Assessment!L7) | E7: =IF(C7<>"",C7*D7,"") | F7: =IF(E7="","", IF(E7<=5,"Low",IF(E7<=10,"Medium", IF(E7<=15,"High","Critical")))) | H7: =IF(E7="","",IF(E7<=$K$4,"Accept","Treat"))
A8: =IF(Risk_Scenarios!H8="","",Risk_Scenarios!H8) | B8: =IF(Risk_Scenarios!I8="","",Risk_Scenarios!I8) | C8: =IF(likelihood!F8="","",likelihood!F8) | D8: =IF(Impact_Assessment!L8="","",Impact_Assessment!L8) | E8: =IF(C8<>"",C8*D8,"") | F8: =IF(E8="","", IF(E8<=5,"Low",IF(E8<=10,"Medium", IF(E8<=15,"High","Critical")))) | H8: =IF(E8="","",IF(E8<=$K$4,"Accept","Treat"))
A9: =IF(Risk_Scenarios!H9="","",Risk_Scenarios!H9) | B9: =IF(Risk_Scenarios!I9="","",Risk_Scenarios!I9) | C9: =IF(likelihood!F9="","",likelihood!F9) | D9: =IF(Impact_Assessment!L9="","",Impact_Assessment!L9) | E9: =IF(C9<>"",C9*D9,"") | F9: =IF(E9="","", IF(E9<=5,"Low",IF(E9<=10,"Medium", IF(E9<=15,"High","Critical")))) | H9: =IF(E9="","",IF(E9<=$K$4,"Accept","Treat"))
A10: =IF(Risk_Scenarios!H10="","",Risk_Scenarios!H10) | B10: =IF(Risk_Scenarios!I10="","",Risk_Scenarios!I10) | C10: =IF(likelihood!F10="","",likelihood!F10) | D10: =IF(Impact_Assessment!L10="","",Impact_Assessment!L10) | E10: =IF(C10<>"",C10*D10,"") | F10: =IF(E10="","", IF(E10<=5,"Low",IF(E10<=10,"Medium", IF(E10<=15,"High","Critical")))) | H10: =IF(E10="","",IF(E10<=$K$4,"Accept","Treat"))
A11: =IF(Risk_Scenarios!H11="","",Risk_Scenarios!H11) | B11: =IF(Risk_Scenarios!I11="","",Risk_Scenarios!I11) | C11: =IF(likelihood!F11="","",likelihood!F11) | D11: =IF(Impact_Assessment!L11="","",Impact_Assessment!L11) | E11: =IF(C11<>"",C11*D11,"") | F11: =IF(E11="","", IF(E11<=5,"Low",IF(E11<=10,"Medium", IF(E11<=15,"High","Critical")))) | H11: =IF(E11="","",IF(E11<=$K$4,"Accept","Treat"))
A12: =IF(Risk_Scenarios!H12="","",Risk_Scenarios!H12) | B12: =IF(Risk_Scenarios!I12="","",Risk_Scenarios!I12) | C12: =IF(likelihood!F12="","",likelihood!F12) | D12: =IF(Impact_Assessment!L12="","",Impact_Assessment!L12) | E12: =IF(C12<>"",C12*D12,"") | F12: =IF(E12="","", IF(E12<=5,"Low",IF(E12<=10,"Medium", IF(E12<=15,"High","Critical")))) | H12: =IF(E12="","",IF(E12<=$K$4,"Accept","Treat"))
A13: =IF(Risk_Scenarios!H13="","",Risk_Scenarios!H13) | C13: =IF(likelihood!F13="","",likelihood!F13) | D13: =IF(Impact_Assessment!L13="","",Impact_Assessment!L13) | E13: =IF(C13<>"",C13*D13,"") | F13: =IF(E13="","", IF(E13<=5,"Low",IF(E13<=10,"Medium", IF(E13<=15,"High","Critical")))) | H13: =IF(E13="","",IF(E13<=$K$4,"Accept","Treat"))
A14: =IF(Risk_Scenarios!H14="","",Risk_Scenarios!H14) | B14: =IF(Risk_Scenarios!I14="","",Risk_Scenarios!I14) | C14: =IF(likelihood!F14="","",likelihood!F14) | D14: =IF(Impact_Assessment!L14="","",Impact_Assessment!L14) | E14: =IF(C14<>"",C14*D14,"") | F14: =IF(E14="","", IF(E14<=5,"Low",IF(E14<=10,"Medium", IF(E14<=15,"High","Critical")))) | H14: =IF(E14="","",IF(E14<=$K$4,"Accept","Treat"))
A15: =IF(Risk_Scenarios!H15="","",Risk_Scenarios!H15) | B15: =IF(Risk_Scenarios!I15="","",Risk_Scenarios!I15) | C15: =IF(likelihood!F15="","",likelihood!F15) | D15: =IF(Impact_Assessment!L15="","",Impact_Assessment!L15) | E15: =IF(C15<>"",C15*D15,"") | F15: =IF(E15="","", IF(E15<=5,"Low",IF(E15<=10,"Medium", IF(E15<=15,"High","Critical")))) | H15: =IF(E15="","",IF(E15<=$K$4,"Accept","Treat"))
A16: =IF(Risk_Scenarios!H16="","",Risk_Scenarios!H16) | B16: =IF(Risk_Scenarios!I16="","",Risk_Scenarios!I16) | C16: =IF(likelihood!F16="","",likelihood!F16) | D16: =IF(Impact_Assessment!L16="","",Impact_Assessment!L16) | E16: =IF(C16<>"",C16*D16,"") | F16: =IF(E16="","", IF(E16<=5,"Low",IF(E16<=10,"Medium", IF(E16<=15,"High","Critical")))) | H16: =IF(E16="","",IF(E16<=$K$4,"Accept","Treat"))
A17: =IF(Risk_Scenarios!H17="","",Risk_Scenarios!H17) | B17: =IF(Risk_Scenarios!I17="","",Risk_Scenarios!I17) | C17: =IF(likelihood!F17="","",likelihood!F17) | D17: =IF(Impact_Assessment!L17="","",Impact_Assessment!L17) | E17: =IF(C17<>"",C17*D17,"") | F17: =IF(E17="","", IF(E17<=5,"Low",IF(E17<=10,"Medium", IF(E17<=15,"High","Critical")))) | H17: =IF(E17="","",IF(E17<=$K$4,"Accept","Treat"))
A18: =IF(Risk_Scenarios!H18="","",Risk_Scenarios!H18) | B18: =IF(Risk_Scenarios!I18="","",Risk_Scenarios!I18) | C18: =IF(likelihood!F18="","",likelihood!F18) | D18: =IF(Impact_Assessment!L18="","",Impact_Assessment!L18) | E18: =IF(C18<>"",C18*D18,"") | F18: =IF(E18="","", IF(E18<=5,"Low",IF(E18<=10,"Medium", IF(E18<=15,"High","Critical")))) | H18: =IF(E18="","",IF(E18<=$K$4,"Accept","Treat"))
A19: =IF(Risk_Scenarios!H19="","",Risk_Scenarios!H19) | B19: =IF(Risk_Scenarios!I19="","",Risk_Scenarios!I19) | C19: =IF(likelihood!F19="","",likelihood!F19) | D19: =IF(Impact_Assessment!L19="","",Impact_Assessment!L19) | E19: =IF(C19<>"",C19*D19,"") | F19: =IF(E19="","", IF(E19<=5,"Low",IF(E19<=10,"Medium", IF(E19<=15,"High","Critical")))) | H19: =IF(E19="","",IF(E19<=$K$4,"Accept","Treat"))
A20: =IF(Risk_Scenarios!H20="","",Risk_Scenarios!H20) | B20: =IF(Risk_Scenarios!I20="","",Risk_Scenarios!I20) | C20: =IF(likelihood!F20="","",likelihood!F20) | D20: =IF(Impact_Assessment!L20="","",Impact_Assessment!L20) | E20: =IF(C20<>"",C20*D20,"") | F20: =IF(E20="","", IF(E20<=5,"Low",IF(E20<=10,"Medium", IF(E20<=15,"High","Critical")))) | H20: =IF(E20="","",IF(E20<=$K$4,"Accept","Treat"))
A21: =IF(Risk_Scenarios!H21="","",Risk_Scenarios!H21) | B21: =IF(Risk_Scenarios!I21="","",Risk_Scenarios!I21) | C21: =IF(likelihood!F21="","",likelihood!F21) | D21: =IF(Impact_Assessment!L21="","",Impact_Assessment!L21) | E21: =IF(C21<>"",C21*D21,"") | F21: =IF(E21="","", IF(E21<=5,"Low",IF(E21<=10,"Medium", IF(E21<=15,"High","Critical")))) | H21: =IF(E21="","",IF(E21<=$K$4,"Accept","Treat"))
A22: =IF(Risk_Scenarios!H22="","",Risk_Scenarios!H22) | B22: =IF(Risk_Scenarios!I22="","",Risk_Scenarios!I22) | C22: =IF(likelihood!F22="","",likelihood!F22) | D22: =IF(Impact_Assessment!L22="","",Impact_Assessment!L22) | E22: =IF(C22<>"",C22*D22,"") | F22: =IF(E22="","", IF(E22<=5,"Low",IF(E22<=10,"Medium", IF(E22<=15,"High","Critical")))) | H22: =IF(E22="","",IF(E22<=$K$4,"Accept","Treat"))
A23: =IF(Risk_Scenarios!H23="","",Risk_Scenarios!H23) | B23: =IF(Risk_Scenarios!I23="","",Risk_Scenarios!I23) | C23: =IF(likelihood!F23="","",likelihood!F23) | D23: =IF(Impact_Assessment!L23="","",Impact_Assessment!L23) | E23: =IF(C23<>"",C23*D23,"") | F23: =IF(E23="","", IF(E23<=5,"Low",IF(E23<=10,"Medium", IF(E23<=15,"High","Critical")))) | H23: =IF(E23="","",IF(E23<=$K$4,"Accept","Treat"))
A24: =IF(Risk_Scenarios!H24="","",Risk_Scenarios!H24) | B24: =IF(Risk_Scenarios!I24="","",Risk_Scenarios!I24) | C24: =IF(likelihood!F24="","",likelihood!F24) | D24: =IF(Impact_Assessment!L24="","",Impact_Assessment!L24) | E24: =IF(C24<>"",C24*D24,"") | F24: =IF(E24="","", IF(E24<=5,"Low",IF(E24<=10,"Medium", IF(E24<=15,"High","Critical")))) | H24: =IF(E24="","",IF(E24<=$K$4,"Accept","Treat"))
A25: =IF(Risk_Scenarios!H25="","",Risk_Scenarios!H25) | B25: =IF(Risk_Scenarios!I25="","",Risk_Scenarios!I25) | C25: =IF(likelihood!F25="","",likelihood!F25) | D25: =IF(Impact_Assessment!L25="","",Impact_Assessment!L25) | E25: =IF(C25<>"",C25*D25,"") | F25: =IF(E25="","", IF(E25<=5,"Low",IF(E25<=10,"Medium", IF(E25<=15,"High","Critical")))) | H25: =IF(E25="","",IF(E25<=$K$4,"Accept","Treat"))
... A31: =IF(Risk_Scenarios!H31="","",Risk_Scenarios!H31) | B31: =IF(Risk_Scenarios!I31="","",Risk_Scenarios!I31) | C31: =IF(likelihood!F31="","",likelihood!F31) | D31: =IF(Impact_Assessment!L31="","",Impact_Assessment!L31) | E31: =IF(C31<>"",C31*D31,"") | F31: =IF(E31="","", IF(E31<=5,"Low",IF(E31<=10,"Medium", IF(E31<=15,"High","Critical")))) | H31: =IF(E31="","",IF(E31<=$K$4,"Accept","Treat"))
C32: =IFERROR(VLOOKUP(B32,likelihood!A:F,6,FALSE),"") | D32: =IF(Impact_Assessment!L32="","",Impact_Assessment!L32) | E32: =IF(C32<>"",C32*D32,"") | F32: =IF(E32="","", IF(E32<=5,"Low",IF(E32<=10,"Medium", IF(E32<=15,"High","Critical")))) | H32: =IF(E32="","",IF(E32<=$K$4,"Accept","Treat"))
C33: =IFERROR(VLOOKUP(B33,likelihood!A:F,6,FALSE),"") | D33: =IFERROR(VLOOKUP(B33,Impact_Assessment!A:L,6,FALSE),"") | E33: =IF(C33<>"",C33*D33,"") | F33: =IF(E33="","", IF(E33<=5,"Low",IF(E33<=10,"Medium", IF(E33<=15,"High","Critical")))) | H33: =IF(E33="","",IF(E33<=$K$4,"Accept","Treat"))
C34: =IFERROR(VLOOKUP(B34,likelihood!A:F,6,FALSE),"") | D34: =IFERROR(VLOOKUP(B34,Impact_Assessment!A:L,6,FALSE),"") | E34: =IF(C34<>"",C34*D34,"") | F34: =IF(E34="","", IF(E34<=5,"Low",IF(E34<=10,"Medium", IF(E34<=15,"High","Critical"))))
C35: =IFERROR(VLOOKUP(B35,likelihood!A:F,6,FALSE),"") | D35: =IFERROR(VLOOKUP(B35,Impact_Assessment!A:L,6,FALSE),"") | E35: =IF(C35<>"",C35*D35,"") | F35: =IF(E35="","", IF(E35<=5,"Low",IF(E35<=10,"Medium", IF(E35<=15,"High","Critical"))))
C36: =IFERROR(VLOOKUP(B36,likelihood!A:F,6,FALSE),"") | D36: =IFERROR(VLOOKUP(B36,Impact_Assessment!A:L,6,FALSE),"") | E36: =IF(C36<>"",C36*D36,"") | F36: =IF(E36="","", IF(E36<=5,"Low",IF(E36<=10,"Medium", IF(E36<=15,"High","Critical"))))
C37: =IFERROR(VLOOKUP(B37,likelihood!A:F,6,FALSE),"") | D37: =IFERROR(VLOOKUP(B37,Impact_Assessment!A:L,6,FALSE),"") | E37: =IF(C37<>"",C37*D37,"") | F37: =IF(E37="","", IF(E37<=5,"Low",IF(E37<=10,"Medium", IF(E37<=15,"High","Critical"))))
C38: =IFERROR(VLOOKUP(B38,likelihood!A:F,6,FALSE),"") | D38: =IFERROR(VLOOKUP(B38,Impact_Assessment!A:L,6,FALSE),"") | E38: =IF(C38<>"",C38*D38,"") | F38: =IF(E38="","", IF(E38<=5,"Low",IF(E38<=10,"Medium", IF(E38<=15,"High","Critical"))))
C39: =IFERROR(VLOOKUP(B39,likelihood!A:F,6,FALSE),"") | D39: =IFERROR(VLOOKUP(B39,Impact_Assessment!A:L,6,FALSE),"") | E39: =IF(C39<>"",C39*D39,"") | F39: =IF(E39="","", IF(E39<=5,"Low",IF(E39<=10,"Medium", IF(E39<=15,"High","Critical"))))
C40: =IFERROR(VLOOKUP(B40,likelihood!A:F,6,FALSE),"") | D40: =IFERROR(VLOOKUP(B40,Impact_Assessment!A:L,6,FALSE),"") | E40: =IF(C40<>"",C40*D40,"") | F40: =IF(E40="","", IF(E40<=5,"Low",IF(E40<=10,"Medium", IF(E40<=15,"High","Critical"))))
C41: =IFERROR(VLOOKUP(B41,likelihood!A:F,6,FALSE),"") | D41: =IFERROR(VLOOKUP(B41,Impact_Assessment!A:L,6,FALSE),"") | E41: =IF(C41<>"",C41*D41,"") | F41: =IF(E41="","", IF(E41<=5,"Low",IF(E41<=10,"Medium", IF(E41<=15,"High","Critical"))))
C42: =IFERROR(VLOOKUP(B42,likelihood!A:F,6,FALSE),"") | D42: =IFERROR(VLOOKUP(B42,Impact_Assessment!A:L,6,FALSE),"") | E42: =IF(C42<>"",C42*D42,"") | F42: =IF(E42="","", IF(E42<=5,"Low",IF(E42<=10,"Medium", IF(E42<=15,"High","Critical"))))
C43: =IFERROR(VLOOKUP(B43,likelihood!A:F,6,FALSE),"") | D43: =IFERROR(VLOOKUP(B43,Impact_Assessment!A:L,6,FALSE),"") | E43: =IF(C43<>"",C43*D43,"") | F43: =IF(E43="","", IF(E43<=5,"Low",IF(E43<=10,"Medium", IF(E43<=15,"High","Critical"))))
C44: =IFERROR(VLOOKUP(B44,likelihood!A:F,6,FALSE),"") | D44: =IFERROR(VLOOKUP(B44,Impact_Assessment!A:L,6,FALSE),"") | E44: =IF(C44<>"",C44*D44,"") | F44: =IF(E44="","", IF(E44<=5,"Low",IF(E44<=10,"Medium", IF(E44<=15,"High","Critical"))))
C45: =IFERROR(VLOOKUP(B45,likelihood!A:F,6,FALSE),"") | D45: =IFERROR(VLOOKUP(B45,Impact_Assessment!A:L,6,FALSE),"") | E45: =IF(C45<>"",C45*D45,"") | F45: =IF(E45="","", IF(E45<=5,"Low",IF(E45<=10,"Medium", IF(E45<=15,"High","Critical"))))
...

Sheet Risk Managment_Mapping
A1: Risk | B1: Risk Score (Inherent) | C1: Risk Treatment | D1: Recommended Controls | E1: Control Type for Impact | F1: Control Type for Likelihood | G1: Effectiveness on Impact | H1: Effectiveness on Likelihood | I1: Residual Impact | J1: Residual Likelihood | K1: Residual Risk Score | L1: Residual Risk Level
A2: =IF(Inherent_Risk_Scores!A2="","",Inherent_Risk_Scores!A2) -> Citizen personal data leaks due to weak authentication controls | B2: =IF(Inherent_Risk_Scores!E2="","",Inherent_Risk_Scores!E2) -> 12 | C2: =IF(Inherent_Risk_Scores!I2="","",Inherent_Risk_Scores!I2) -> Mitigate | D2: Apply PMA Apply Strong Policy | E2: - | F2: Preventive | G2: 0 | H2: 3 | I2: =IF(OR(Impact_Assessment!L2="",G2=""),"",MAX(1,Impact_Assessment!L2-G2)) -> 3 | J2: =IF(OR(likelihood!F2="",H2=""),"",MAX(1,likelihood!F2-H2)) -> 1 | K2: =IF(I2<>"",I2*J2,"") -> 3 | L2: =IF(K2="","", IF(K2<=5,"Low", IF(K2<=10,"Medium", IF(K2<=15,"High","Critical")))) -> Low
A3: =IF(Inherent_Risk_Scores!A3="","",Inherent_Risk_Scores!A3) | B3: =IF(Inherent_Risk_Scores!E3="","",Inherent_Risk_Scores!E3) | C3: =IF(Inherent_Risk_Scores!I3="","",Inherent_Risk_Scores!I3) | I3: =IF(OR(Impact_Assessment!L3="",G3=""),"",MAX(1,Impact_Assessment!L3-G3)) | J3: =IF(OR(likelihood!F3="",H3=""),"",MAX(1,likelihood!F3-H3)) | K3: =IF(I3<>"",I3*J3,"") | L3: =IF(K3="","", IF(K3<=5,"Low", IF(K3<=10,"Medium", IF(K3<=15,"High","Critical"))))
A4: =IF(Inherent_Risk_Scores!A4="","",Inherent_Risk_Scores!A4) | B4: =IF(Inherent_Risk_Scores!E4="","",Inherent_Risk_Scores!E4) | C4: =IF(Inherent_Risk_Scores!I4="","",Inherent_Risk_Scores!I4) | I4: =IF(OR(Impact_Assessment!L4="",G4=""),"",MAX(1,Impact_Assessment!L4-G4)) | J4: =IF(OR(likelihood!F4="",H4=""),"",MAX(1,likelihood!F4-H4)) | K4: =IF(I4<>"",I4*J4,"") | L4: =IF(K4="","", IF(K4<=5,"Low", IF(K4<=10,"Medium", IF(K4<=15,"High","Critical"))))
A5: =IF(Inherent_Risk_Scores!A5="","",Inherent_Risk_Scores!A5) | B5: =IF(Inherent_Risk_Scores!E5="","",Inherent_Risk_Scores!E5) | C5: =IF(Inherent_Risk_Scores!I5="","",Inherent_Risk_Scores!I5) | I5: =IF(OR(Impact_Assessment!L5="",G5=""),"",MAX(1,Impact_Assessment!L5-G5)) | J5: =IF(OR(likelihood!F5="",H5=""),"",MAX(1,likelihood!F5-H5)) | K5: =IF(I5<>"",I5*J5,"") | L5: =IF(K5="","", IF(K5<=5,"Low", IF(K5<=10,"Medium", IF(K5<=15,"High","Critical"))))
A6: =IF(Inherent_Risk_Scores!A6="","",Inherent_Risk_Scores!A6) | B6: =IF(Inherent_Risk_Scores!E6="","",Inherent_Risk_Scores!E6) | C6: =IF(Inherent_Risk_Scores!I6="","",Inherent_Risk_Scores!I6) | I6: =IF(OR(Impact_Assessment!L6="",G6=""),"",MAX(1,Impact_Assessment!L6-G6)) | J6: =IF(OR(likelihood!F6="",H6=""),"",MAX(1,likelihood!F6-H6)) | K6: =IF(I6<>"",I6*J6,"") | L6: =IF(K6="","", IF(K6<=5,"Low", IF(K6<=10,"Medium", IF(K6<=15,"High","Critical"))))
A7: =IF(Inherent_Risk_Scores!A7="","",Inherent_Risk_Scores!A7) | B7: =IF(Inherent_Risk_Scores!E7="","",Inherent_Risk_Scores!E7) | C7: =IF(Inherent_Risk_Scores!I7="","",Inherent_Risk_Scores!I7) | I7: =IF(OR(Impact_Assessment!L7="",G7=""),"",MAX(1,Impact_Assessment!L7-G7)) | J7: =IF(OR(likelihood!F7="",H7=""),"",MAX(1,likelihood!F7-H7)) | K7: =IF(I7<>"",I7*J7,"") | L7: =IF(K7="","", IF(K7<=5,"Low", IF(K7<=10,"Medium", IF(K7<=15,"High","Critical"))))
A8: =IF(Inherent_Risk_Scores!A8="","",Inherent_Risk_Scores!A8) | B8: =IF(Inherent_Risk_Scores!E8="","",Inherent_Risk_Scores!E8) | C8: =IF(Inherent_Risk_Scores!I8="","",Inherent_Risk_Scores!I8) | I8: =IF(OR(Impact_Assessment!L8="",G8=""),"",MAX(1,Impact_Assessment!L8-G8)) | J8: =IF(OR(likelihood!F8="",H8=""),"",MAX(1,likelihood!F8-H8)) | K8: =IF(I8<>"",I8*J8,"") | L8: =IF(K8="","", IF(K8<=5,"Low", IF(K8<=10,"Medium", IF(K8<=15,"High","Critical"))))
A9: =IF(Inherent_Risk_Scores!A9="","",Inherent_Risk_Scores!A9) | B9: =IF(Inherent_Risk_Scores!E9="","",Inherent_Risk_Scores!E9) | C9: =IF(Inherent_Risk_Scores!I9="","",Inherent_Risk_Scores!I9) | I9: =IF(OR(Impact_Assessment!L9="",G9=""),"",MAX(1,Impact_Assessment!L9-G9)) | J9: =IF(OR(likelihood!F9="",H9=""),"",MAX(1,likelihood!F9-H9)) | K9: =IF(I9<>"",I9*J9,"") | L9: =IF(K9="","", IF(K9<=5,"Low", IF(K9<=10,"Medium", IF(K9<=15,"High","Critical"))))
A10: =IF(Inherent_Risk_Scores!A10="","",Inherent_Risk_Scores!A10) | B10: =IF(Inherent_Risk_Scores!E10="","",Inherent_Risk_Scores!E10) | C10: =IF(Inherent_Risk_Scores!I10="","",Inherent_Risk_Scores!I10) | I10: =IF(OR(Impact_Assessment!L10="",G10=""),"",MAX(1,Impact_Assessment!L10-G10)) | J10: =IF(OR(likelihood!F10="",H10=""),"",MAX(1,likelihood!F10-H10)) | K10: =IF(I10<>"",I10*J10,"") | L10: =IF(K10="","", IF(K10<=5,"Low", IF(K10<=10,"Medium", IF(K10<=15,"High","Critical"))))
A11: =IF(Inherent_Risk_Scores!A11="","",Inherent_Risk_Scores!A11) | B11: =IF(Inherent_Risk_Scores!E11="","",Inherent_Risk_Scores!E11) | C11: =IF(Inherent_Risk_Scores!I11="","",Inherent_Risk_Scores!I11) | I11: =IF(OR(Impact_Assessment!L11="",G11=""),"",MAX(1,Impact_Assessment!L11-G11)) | J11: =IF(OR(likelihood!F11="",H11=""),"",MAX(1,likelihood!F11-H11)) | K11: =IF(I11<>"",I11*J11,"") | L11: =IF(K11="","", IF(K11<=5,"Low", IF(K11<=10,"Medium", IF(K11<=15,"High","Critical"))))
A12: =IF(Inherent_Risk_Scores!A12="","",Inherent_Risk_Scores!A12) | B12: =IF(Inherent_Risk_Scores!E12="","",Inherent_Risk_Scores!E12) | C12: =IF(Inherent_Risk_Scores!I12="","",Inherent_Risk_Scores!I12) | K12: =IF(I12<>"",I12*J12,"") | L12: =IF(K12="","", IF(K12<=5,"Low", IF(K12<=10,"Medium", IF(K12<=15,"High","Critical"))))
A13: =IF(Inherent_Risk_Scores!A13="","",Inherent_Risk_Scores!A13) | B13: =IF(Inherent_Risk_Scores!E13="","",Inherent_Risk_Scores!E13) | C13: =IF(Inherent_Risk_Scores!I13="","",Inherent_Risk_Scores!I13) | I13: =IF(OR(Impact_Assessment!L13="",G13=""),"",MAX(1,Impact_Assessment!L13-G13)) | J13: =IF(OR(likelihood!F13="",H13=""),"",MAX(1,likelihood!F13-H13)) | K13: =IF(I13<>"",I13*J13,"") | L13: =IF(K13="","", IF(K13<=5,"Low", IF(K13<=10,"Medium", IF(K13<=15,"High","Critical"))))
A14: =IF(Inherent_Risk_Scores!A14="","",Inherent_Risk_Scores!A14) | B14: =IF(Inherent_Risk_Scores!E14="","",Inherent_Risk_Scores!E14) | C14: =IF(Inherent_Risk_Scores!I14="","",Inherent_Risk_Scores!I14) | I14: =IF(OR(Impact_Assessment!L14="",G14=""),"",MAX(1,Impact_Assessment!L14-G14)) | J14: =IF(OR(likelihood!F14="",H14=""),"",MAX(1,likelihood!F14-H14)) | K14: =IF(I14<>"",I14*J14,"") | L14: =IF(K14="","", IF(K14<=5,"Low", IF(K14<=10,"Medium", IF(K14<=15,"High","Critical"))))
A15: =IF(Inherent_Risk_Scores!A15="","",Inherent_Risk_Scores!A15) | B15: =IF(Inherent_Risk_Scores!E15="","",Inherent_Risk_Scores!E15) | C15: =IF(Inherent_Risk_Scores!I16="","",Inherent_Risk_Scores!I16) | I15: =IF(OR(Impact_Assessment!L15="",G15=""),"",MAX(1,Impact_Assessment!L15-G15)) | J15: =IF(OR(likelihood!F15="",H15=""),"",MAX(1,likelihood!F15-H15)) | K15: =IF(I15<>"",I15*J15,"") | L15: =IF(K15="","", IF(K15<=5,"Low", IF(K15<=10,"Medium", IF(K15<=15,"High","Critical"))))
A16: =IF(Inherent_Risk_Scores!A16="","",Inherent_Risk_Scores!A16) | B16: =IF(Inherent_Risk_Scores!E16="","",Inherent_Risk_Scores!E16) | C16: =IF(Inherent_Risk_Scores!I17="","",Inherent_Risk_Scores!I17) | I16: =IF(OR(Impact_Assessment!L16="",G16=""),"",MAX(1,Impact_Assessment!L16-G16)) | J16: =IF(OR(likelihood!F16="",H16=""),"",MAX(1,likelihood!F16-H16)) | K16: =IF(I16<>"",I16*J16,"") | L16: =IF(K16="","", IF(K16<=5,"Low", IF(K16<=10,"Medium", IF(K16<=15,"High","Critical"))))
A17: =IF(Inherent_Risk_Scores!A17="","",Inherent_Risk_Scores!A17) | B17: =IF(Inherent_Risk_Scores!E17="","",Inherent_Risk_Scores!E17) | C17: =IF(Inherent_Risk_Scores!I18="","",Inherent_Risk_Scores!I18) | I17: =IF(OR(Impact_Assessment!L17="",G17=""),"",MAX(1,Impact_Assessment!L17-G17)) | J17: =IF(OR(likelihood!F17="",H17=""),"",MAX(1,likelihood!F17-H17)) | K17: =IF(I17<>"",I17*J17,"") | L17: =IF(K17="","", IF(K17<=5,"Low", IF(K17<=10,"Medium", IF(K17<=15,"High","Critical"))))
A18: =IF(Inherent_Risk_Scores!A18="","",Inherent_Risk_Scores!A18) | B18: =IF(Inherent_Risk_Scores!E18="","",Inherent_Risk_Scores!E18) | C18: =IF(Inherent_Risk_Scores!I19="","",Inherent_Risk_Scores!I19) | I18: =IF(OR(Impact_Assessment!L18="",G18=""),"",MAX(1,Impact_Assessment!L18-G18)) | J18: =IF(OR(likelihood!F18="",H18=""),"",MAX(1,likelihood!F18-H18)) | K18: =IF(I18<>"",I18*J18,"") | L18: =IF(K18="","", IF(K18<=5,"Low", IF(K18<=10,"Medium", IF(K18<=15,"High","Critical"))))
A19: =IF(Inherent_Risk_Scores!A19="","",Inherent_Risk_Scores!A19) | B19: =IF(Inherent_Risk_Scores!E19="","",Inherent_Risk_Scores!E19) | C19: =IF(Inherent_Risk_Scores!I20="","",Inherent_Risk_Scores!I20) | I19: =IF(OR(Impact_Assessment!L19="",G19=""),"",MAX(1,Impact_Assessment!L19-G19)) | J19: =IF(OR(likelihood!F19="",H19=""),"",MAX(1,likelihood!F19-H19)) | K19: =IF(I19<>"",I19*J19,"") | L19: =IF(K19="","", IF(K19<=5,"Low", IF(K19<=10,"Medium", IF(K19<=15,"High","Critical"))))
A20: =IF(Inherent_Risk_Scores!A20="","",Inherent_Risk_Scores!A20) | B20: =IF(Inherent_Risk_Scores!E20="","",Inherent_Risk_Scores!E20) | C20: =IF(Inherent_Risk_Scores!I21="","",Inherent_Risk_Scores!I21) | I20: =IF(OR(Impact_Assessment!L20="",G20=""),"",MAX(1,Impact_Assessment!L20-G20)) | J20: =IF(OR(likelihood!F20="",H20=""),"",MAX(1,likelihood!F20-H20)) | K20: =IF(I20<>"",I20*J20,"") | L20: =IF(K20="","", IF(K20<=5,"Low", IF(K20<=10,"Medium", IF(K20<=15,"High","Critical"))))
A21: =IF(Inherent_Risk_Scores!A21="","",Inherent_Risk_Scores!A21) | B21: =IF(Inherent_Risk_Scores!E21="","",Inherent_Risk_Scores!E21) | C21: =IF(Inherent_Risk_Scores!I22="","",Inherent_Risk_Scores!I22) | I21: =IF(OR(Impact_Assessment!L21="",G21=""),"",MAX(1,Impact_Assessment!L21-G21)) | J21: =IF(OR(likelihood!F21="",H21=""),"",MAX(1,likelihood!F21-H21)) | K21: =IF(I21<>"",I21*J21,"") | L21: =IF(K21="","", IF(K21<=5,"Low", IF(K21<=10,"Medium", IF(K21<=15,"High","Critical"))))
A22: =IF(Inherent_Risk_Scores!A22="","",Inherent_Risk_Scores!A22) | B22: =IF(Inherent_Risk_Scores!E22="","",Inherent_Risk_Scores!E22) | C22: =IF(Inherent_Risk_Scores!I23="","",Inherent_Risk_Scores!I23) | I22: =IF(OR(Impact_Assessment!L22="",G22=""),"",MAX(1,Impact_Assessment!L22-G22)) | J22: =IF(OR(likelihood!F22="",H22=""),"",MAX(1,likelihood!F22-H22)) | K22: =IF(I22<>"",I22*J22,"") | L22: =IF(K22="","", IF(K22<=5,"Low", IF(K22<=10,"Medium", IF(K22<=15,"High","Critical"))))
A23: =IF(Inherent_Risk_Scores!A23="","",Inherent_Risk_Scores!A23) | B23: =IF(Inherent_Risk_Scores!E23="","",Inherent_Risk_Scores!E23) | C23: =IF(Inherent_Risk_Scores!I24="","",Inherent_Risk_Scores!I24) | I23: =IF(OR(Impact_Assessment!L23="",G23=""),"",MAX(1,Impact_Assessment!L23-G23)) | J23: =IF(OR(likelihood!F23="",H23=""),"",MAX(1,likelihood!F23-H23)) | K23: =IF(I23<>"",I23*J23,"") | L23: =IF(K23="","", IF(K23<=5,"Low", IF(K23<=10,"Medium", IF(K23<=15,"High","Critical"))))
A24: =IF(Inherent_Risk_Scores!A24="","",Inherent_Risk_Scores!A24) | B24: =IF(Inherent_Risk_Scores!E24="","",Inherent_Risk_Scores!E24) | C24: =IF(Inherent_Risk_Scores!I25="","",Inherent_Risk_Scores!I25) | I24: =IF(OR(Impact_Assessment!L24="",G24=""),"",MAX(1,Impact_Assessment!L24-G24)) | J24: =IF(OR(likelihood!F24="",H24=""),"",MAX(1,likelihood!F24-H24)) | K24: =IF(I24<>"",I24*J24,"") | L24: =IF(K24="","", IF(K24<=5,"Low", IF(K24<=10,"Medium", IF(K24<=15,"High","Critical"))))
A25: =IF(Inherent_Risk_Scores!A25="","",Inherent_Risk_Scores!A25) | B25: =IF(Inherent_Risk_Scores!E25="","",Inherent_Risk_Scores!E25) | C25: =IF(Inherent_Risk_Scores!I26="","",Inherent_Risk_Scores!I26) | I25: =IF(OR(Impact_Assessment!L25="",G25=""),"",MAX(1,Impact_Assessment!L25-G25)) | J25: =IF(OR(likelihood!F25="",H25=""),"",MAX(1,likelihood!F25-H25)) | K25: =IF(I25<>"",I25*J25,"") | L25: =IF(K25="","", IF(K25<=5,"Low", IF(K25<=10,"Medium", IF(K25<=15,"High","Critical"))))
A26: =IF(Inherent_Risk_Scores!A26="","",Inherent_Risk_Scores!A26) | B26: =IF(Inherent_Risk_Scores!E26="","",Inherent_Risk_Scores!E26) | C26: =IF(Inherent_Risk_Scores!I27="","",Inherent_Risk_Scores!I27) | I26: =IF(OR(Impact_Assessment!L26="",G26=""),"",MAX(1,Impact_Assessment!L26-G26)) | J26: =IF(OR(likelihood!F26="",H26=""),"",MAX(1,likelihood!F26-H26)) | K26: =IF(I26<>"",I26*J26,"") | L26: =IF(K26="","", IF(K26<=5,"Low", IF(K26<=10,"Medium", IF(K26<=15,"High","Critical"))))
... A31: =IF(Inherent_Risk_Scores!A31="","",Inherent_Risk_Scores!A31) | B31: =IF(Inherent_Risk_Scores!E31="","",Inherent_Risk_Scores!E31) | C31: =IF(Inherent_Risk_Scores!I32="","",Inherent_Risk_Scores!I32) | I31: =IF(OR(Impact_Assessment!L31="",G31=""),"",MAX(1,Impact_Assessment!L31-G31)) | J31: =IF(OR(likelihood!F31="",H31=""),"",MAX(1,likelihood!F31-H31)) | K31: =IF(I31<>"",I31*J31,"") | L31: =IF(K31="","", IF(K31<=5,"Low", IF(K31<=10,"Medium", IF(K31<=15,"High","Critical"))))
B32: =IF(Inherent_Risk_Scores!E33="","",Inherent_Risk_Scores!B33) | C32: =IF(Inherent_Risk_Scores!I33="","",Inherent_Risk_Scores!I33) | I32: =IF(OR(Impact_Assessment!L32="",G32=""),"",Impact_Assessment!L32-G32) | J32: =IF(OR(likelihood!F32="",H32=""),"",MAX(1,likelihood!F32-H32)) | K32: =IF(I32<>"",I32*J32,"") | L32: =IF(K32="","", IF(K32<=5,"Low", IF(K32<=10,"Medium", IF(K32<=15,"High","Critical"))))
C33: =IF(Inherent_Risk_Scores!I34="","",Inherent_Risk_Scores!I34) | I33: =IF(OR(Impact_Assessment!L33="",G33=""),"",Impact_Assessment!L33-G33) | J33: =IF(OR(likelihood!F33="",H33=""),"",MAX(1,likelihood!F33-H33)) | K33: =IF(I33<>"",I33*J33,"") | L33: =IF(K33="","", IF(K33<=5,"Low", IF(K33<=10,"Medium", IF(K33<=15,"High","Critical"))))
C34: =IF(Inherent_Risk_Scores!I35="","",Inherent_Risk_Scores!I35) | I34: =IF(OR(Impact_Assessment!L34="",G34=""),"",Impact_Assessment!L34-G34) | K34: =IF(I34<>"",I34*J34,"") | L34: =IF(K34="","", IF(K34<=5,"Low", IF(K34<=10,"Medium", IF(K34<=15,"High","Critical"))))
C35: =IF(Inherent_Risk_Scores!I36="","",Inherent_Risk_Scores!I36) | I35: =IF(OR(Impact_Assessment!L35="",G35=""),"",Impact_Assessment!L35-G35) | K35: =IF(I35<>"",I35*J35,"") | L35: =IF(K35="","", IF(K35<=5,"Low", IF(K35<=10,"Medium", IF(K35<=15,"High","Critical"))))
C36: =IF(Inherent_Risk_Scores!I37="","",Inherent_Risk_Scores!I37) | I36: =IF(OR(Impact_Assessment!L36="",G36=""),"",Impact_Assessment!L36-G36) | K36: =IF(I36<>"",I36*J36,"") | L36: =IF(K36="","", IF(K36<=5,"Low", IF(K36<=10,"Medium", IF(K36<=15,"High","Critical"))))
C37: =IF(Inherent_Risk_Scores!I38="","",Inherent_Risk_Scores!I38) | I37: =IF(OR(Impact_Assessment!L37="",G37=""),"",Impact_Assessment!L37-G37) | K37: =IF(I37<>"",I37*J37,"") | L37: =IF(K37="","", IF(K37<=5,"Low", IF(K37<=10,"Medium", IF(K37<=15,"High","Critical"))))
C38: =IF(Inherent_Risk_Scores!I39="","",Inherent_Risk_Scores!I39) | I38: =IF(OR(Impact_Assessment!L38="",G38=""),"",Impact_Assessment!L38-G38) | K38: =IF(I38<>"",I38*J38,"") | L38: =IF(K38="","", IF(K38<=5,"Low", IF(K38<=10,"Medium", IF(K38<=15,"High","Critical"))))
C39: =IF(Inherent_Risk_Scores!I40="","",Inherent_Risk_Scores!I40) | I39: =IF(OR(Impact_Assessment!L39="",G39=""),"",Impact_Assessment!L39-G39) | K39: =IF(I39<>"",I39*J39,"") | L39: =IF(K39="","", IF(K39<=5,"Low", IF(K39<=10,"Medium", IF(K39<=15,"High","Critical"))))
C40: =IF(Inherent_Risk_Scores!I41="","",Inherent_Risk_Scores!I41) | K40: =IF(I40<>"",I40*J40,"") | L40: =IF(K40="","", IF(K40<=5,"Low", IF(K40<=10,"Medium", IF(K40<=15,"High","Critical"))))
K41: =IF(I41<>"",I41*J41,"") | L41: =IF(K41="","", IF(K41<=5,"Low", IF(K41<=10,"Medium", IF(K41<=15,"High","Critical"))))
K42: =IF(I42<>"",I42*J42,"")
K43: =IF(I43<>"",I43*J43,"")
K44: =IF(I44<>"",I44*J44,"")
...

Sheet R_A_Chart
C13: Low
C14: Medium
C15: High
C16: Critical
